{
 "cells": [
  {
   "cell_type": "code",
   "execution_count": 3,
   "id": "dd4134c9",
   "metadata": {},
   "outputs": [],
   "source": [
    "from utils import (\n",
    "    generate_with_single_input, \n",
    "    generate_with_multiple_input\n",
    ")"
   ]
  },
  {
   "cell_type": "code",
   "execution_count": 4,
   "id": "5ac6b6c1",
   "metadata": {},
   "outputs": [
    {
     "name": "stderr",
     "output_type": "stream",
     "text": [
      "c:\\Users\\cabe\\Documents\\courses\\DLAI\\RAG\\ragprod\\.venv\\Lib\\site-packages\\urllib3\\connectionpool.py:1097: InsecureRequestWarning: Unverified HTTPS request is being made to host 'proxy.dlai.link'. Adding certificate verification is strongly advised. See: https://urllib3.readthedocs.io/en/latest/advanced-usage.html#tls-warnings\n",
      "  warnings.warn(\n"
     ]
    },
    {
     "ename": "Exception",
     "evalue": "Error while calling LLM: f<!DOCTYPE HTML PUBLIC \"-//W3C//DTD HTML 4.01 Transitional//EN\" \"http://www.w3.org/TR/html4/loose.dtd\">\n<HTML><HEAD><META HTTP-EQUIV=\"Content-Type\" CONTENT=\"text/html; charset=iso-8859-1\">\n<TITLE>ERROR: The request could not be satisfied</TITLE>\n</HEAD><BODY>\n<H1>403 ERROR</H1>\n<H2>The request could not be satisfied.</H2>\n<HR noshade size=\"1px\">\nRequest blocked.\nWe can't connect to the server for this app or website at this time. There might be too much traffic or a configuration error. Try again later, or contact the app or website owner.\n<BR clear=\"all\">\nIf you provide content to customers through CloudFront, you can find steps to troubleshoot and help prevent this error by reviewing the CloudFront documentation.\n<BR clear=\"all\">\n<HR noshade size=\"1px\">\n<PRE>\nGenerated by cloudfront (CloudFront)\nRequest ID: coffsoazUYcvrd8Bu9e1g69R-fzypVjX2SfHeFkldOicvgyHWFHgZw==\n</PRE>\n<ADDRESS>\n</ADDRESS>\n</BODY></HTML>",
     "output_type": "error",
     "traceback": [
      "\u001b[31m---------------------------------------------------------------------------\u001b[39m",
      "\u001b[31mException\u001b[39m                                 Traceback (most recent call last)",
      "\u001b[36mCell\u001b[39m\u001b[36m \u001b[39m\u001b[32mIn[4]\u001b[39m\u001b[32m, line 2\u001b[39m\n\u001b[32m      1\u001b[39m \u001b[38;5;66;03m# Example call\u001b[39;00m\n\u001b[32m----> \u001b[39m\u001b[32m2\u001b[39m output = \u001b[43mgenerate_with_single_input\u001b[49m\u001b[43m(\u001b[49m\n\u001b[32m      3\u001b[39m \u001b[43m    \u001b[49m\u001b[43mprompt\u001b[49m\u001b[43m=\u001b[49m\u001b[33;43m\"\u001b[39;49m\u001b[33;43mWhat is the capital of France?\u001b[39;49m\u001b[33;43m\"\u001b[39;49m\n\u001b[32m      4\u001b[39m \u001b[43m)\u001b[49m\n\u001b[32m      6\u001b[39m \u001b[38;5;28mprint\u001b[39m(\u001b[33m\"\u001b[39m\u001b[33mRole:\u001b[39m\u001b[33m\"\u001b[39m, output[\u001b[33m'\u001b[39m\u001b[33mrole\u001b[39m\u001b[33m'\u001b[39m])\n\u001b[32m      7\u001b[39m \u001b[38;5;28mprint\u001b[39m(\u001b[33m\"\u001b[39m\u001b[33mContent:\u001b[39m\u001b[33m\"\u001b[39m, output[\u001b[33m'\u001b[39m\u001b[33mcontent\u001b[39m\u001b[33m'\u001b[39m])\n",
      "\u001b[36mFile \u001b[39m\u001b[32mc:\\Users\\cabe\\Documents\\courses\\DLAI\\RAG\\ragprod\\notebooks\\utils.py:33\u001b[39m, in \u001b[36mgenerate_with_single_input\u001b[39m\u001b[34m(prompt, role, top_p, temperature, max_tokens, model, together_api_key, **kwargs)\u001b[39m\n\u001b[32m     31\u001b[39m response = requests.post(url, json = payload, verify=\u001b[38;5;28;01mFalse\u001b[39;00m)\n\u001b[32m     32\u001b[39m \u001b[38;5;28;01mif\u001b[39;00m \u001b[38;5;129;01mnot\u001b[39;00m response.ok:\n\u001b[32m---> \u001b[39m\u001b[32m33\u001b[39m     \u001b[38;5;28;01mraise\u001b[39;00m \u001b[38;5;167;01mException\u001b[39;00m(\u001b[33mf\u001b[39m\u001b[33m\"\u001b[39m\u001b[33mError while calling LLM: f\u001b[39m\u001b[38;5;132;01m{\u001b[39;00mresponse.text\u001b[38;5;132;01m}\u001b[39;00m\u001b[33m\"\u001b[39m)\n\u001b[32m     34\u001b[39m \u001b[38;5;28;01mtry\u001b[39;00m:\n\u001b[32m     35\u001b[39m     json_dict = json.loads(response.text)\n",
      "\u001b[31mException\u001b[39m: Error while calling LLM: f<!DOCTYPE HTML PUBLIC \"-//W3C//DTD HTML 4.01 Transitional//EN\" \"http://www.w3.org/TR/html4/loose.dtd\">\n<HTML><HEAD><META HTTP-EQUIV=\"Content-Type\" CONTENT=\"text/html; charset=iso-8859-1\">\n<TITLE>ERROR: The request could not be satisfied</TITLE>\n</HEAD><BODY>\n<H1>403 ERROR</H1>\n<H2>The request could not be satisfied.</H2>\n<HR noshade size=\"1px\">\nRequest blocked.\nWe can't connect to the server for this app or website at this time. There might be too much traffic or a configuration error. Try again later, or contact the app or website owner.\n<BR clear=\"all\">\nIf you provide content to customers through CloudFront, you can find steps to troubleshoot and help prevent this error by reviewing the CloudFront documentation.\n<BR clear=\"all\">\n<HR noshade size=\"1px\">\n<PRE>\nGenerated by cloudfront (CloudFront)\nRequest ID: coffsoazUYcvrd8Bu9e1g69R-fzypVjX2SfHeFkldOicvgyHWFHgZw==\n</PRE>\n<ADDRESS>\n</ADDRESS>\n</BODY></HTML>"
     ]
    }
   ],
   "source": [
    "# Example call\n",
    "output = generate_with_single_input(\n",
    "    prompt=\"What is the capital of France?\"\n",
    ")\n",
    "\n",
    "print(\"Role:\", output['role'])\n",
    "print(\"Content:\", output['content'])"
   ]
  },
  {
   "cell_type": "code",
   "execution_count": null,
   "id": "89884d1a",
   "metadata": {},
   "outputs": [],
   "source": []
  }
 ],
 "metadata": {
  "kernelspec": {
   "display_name": ".venv",
   "language": "python",
   "name": "python3"
  },
  "language_info": {
   "codemirror_mode": {
    "name": "ipython",
    "version": 3
   },
   "file_extension": ".py",
   "mimetype": "text/x-python",
   "name": "python",
   "nbconvert_exporter": "python",
   "pygments_lexer": "ipython3",
   "version": "3.12.9"
  }
 },
 "nbformat": 4,
 "nbformat_minor": 5
}
